<?xml version="1.0" ?>
<robot name="converted_robot">
   <!--generated with mjcf_urdf_simple_converter (https://github.com/Yasu31/mjcf_urdf_simple_converter)-->
   <link name="world">
      <inertial>
         <origin xyz="0.0 0.0 0.0" rpy="0.0 0.0 0.0"/>
         <mass value="0.0"/>
         <inertia ixx="0.0" iyy="0.0" izz="0.0" ixy="0" ixz="0" iyz="0"/>
      </inertial>
   </link>
   <link name="table">
      <inertial>
         <origin xyz="0.0 0.0 -0.015000000000000001" rpy="3.141592653589793 -1.5707963267948966 0.0"/>
         <mass value="27.870910883789055"/>
         <inertia ixx="4.800979286633" iyy="3.4544798400153813" izz="1.3506800832501862" ixy="0" ixz="0" iyz="0"/>
      </inertial>
      <visual name="tabletop">
         <origin xyz="0.0 0.0 -0.015000000000000001" rpy="3.141592653589793 -1.5707963267948966 0.0"/>
         <geometry>
            <mesh filename="meshes/converted_tabletop.stl"/>
         </geometry>
         <material name="white"/>
      </visual>
   </link>
   <joint type="fixed" name="world2table_fixed">
      <parent link="world"/>
      <child link="table"/>
      <origin xyz="0.0 0.6 0.0" rpy="0.0 0.0 0.0"/>
   </joint>
   <link name="midair">
      <inertial>
         <origin xyz="0.0 0.6 0.2" rpy="0.0 0.0 0.0"/>
         <mass value="0.0"/>
         <inertia ixx="0.0" iyy="0.0" izz="0.0" ixy="0" ixz="0" iyz="0"/>
      </inertial>
   </link>
   <joint type="fixed" name="world2midair_fixed">
      <parent link="world"/>
      <child link="midair"/>
      <origin xyz="0.0 0.6 0.2" rpy="0.0 0.0 0.0"/>
   </joint>
   <link name="vx300s_left">
      <inertial>
         <origin xyz="-0.03784382902588578 2.8602218040311562e-08 0.02913398715850308" rpy="0.0 -1.542175771520014 3.141592653589793"/>
         <mass value="2.0847071932290793"/>
         <inertia ixx="0.012833192082346331" iyy="0.010945761787034795" izz="0.003713297010020567" ixy="0" ixz="0" iyz="0"/>
      </inertial>
      <visual name="vx300s_1_base">
         <origin xyz="-0.03784382902588578 2.8602218040311562e-08 0.02913398715850308" rpy="0.0 -1.542175771520014 3.141592653589793"/>
         <geometry>
            <mesh filename="meshes/converted_vx300s_1_base.stl"/>
         </geometry>
         <material name="white"/>
      </visual>
   </link>
   <joint type="fixed" name="world2vx300s_left_fixed">
      <parent link="world"/>
      <child link="vx300s_left"/>
      <origin xyz="-0.469 0.5 0.0" rpy="0.0 0.0 0.0"/>
   </joint>
   <link name="vx300s_left/shoulder_link">
      <inertial>
         <origin xyz="0.000259233 -3.3552e-06 0.0116129" rpy="1.5700255645350394 -1.4773483355619266 -3.140821891329936"/>
         <mass value="0.798614"/>
         <inertia ixx="0.00120156" iyy="0.00113744" izz="0.0009388" ixy="0" ixz="0" iyz="0"/>
      </inertial>
      <visual name="vx300s_2_shoulder">
         <origin xyz="0.0006325719563753528 7.750435013387896e-11 0.02039145786401413" rpy="-1.5707963267948966 -1.5707963267948966 0.0"/>
         <geometry>
            <mesh filename="meshes/converted_vx300s_2_shoulder.stl"/>
         </geometry>
         <material name="white"/>
      </visual>
   </link>
   <link name="vx300s_left/waist_jointbody">
      <inertial>
         <origin xyz="0.0 0.0 0.0" rpy="0.0 0.0 0.0"/>
         <mass value="0.001"/>
         <inertia ixx="1e-09" iyy="1e-09" izz="1e-09" ixy="0" ixz="0" iyz="0"/>
      </inertial>
   </link>
   <joint type="revolute" name="vx300s_left/waist">
      <parent link="vx300s_left"/>
      <child link="vx300s_left/waist_jointbody"/>
      <origin xyz="0.0 0.0 0.079" rpy="0.0 0.0 0.0"/>
      <axis xyz="0.0 0.0 1.0"/>
      <limit lower="-3.14158" upper="3.14158" effort="100" velocity="100"/>
   </joint>
   <joint type="fixed" name="vx300s_left/waist_offset">
      <parent link="vx300s_left/waist_jointbody"/>
      <child link="vx300s_left/shoulder_link"/>
      <origin xyz="-0.0 -0.0 -0.0" rpy="0.0 0.0 0.0"/>
   </joint>
   <link name="vx300s_left/upper_arm_link">
      <inertial>
         <origin xyz="0.0206949 4e-10 0.226459" rpy="0.0 -0.14582079239240509 3.141592653589793"/>
         <mass value="0.792592"/>
         <inertia ixx="0.00911338" iyy="0.008925" izz="0.000759317" ixy="0" ixz="0" iyz="0"/>
      </inertial>
      <visual name="vx300s_3_upper_arm">
         <origin xyz="0.01879484718495746 1.0688876592918973e-09 0.20381388688857144" rpy="0.0 -0.1374703277880469 3.141592653589793"/>
         <geometry>
            <mesh filename="meshes/converted_vx300s_3_upper_arm.stl"/>
         </geometry>
         <material name="white"/>
      </visual>
   </link>
   <link name="vx300s_left/shoulder_jointbody">
      <inertial>
         <origin xyz="0.0 0.0 0.0" rpy="0.0 0.0 0.0"/>
         <mass value="0.001"/>
         <inertia ixx="1e-09" iyy="1e-09" izz="1e-09" ixy="0" ixz="0" iyz="0"/>
      </inertial>
   </link>
   <joint type="revolute" name="vx300s_left/shoulder">
      <parent link="vx300s_left/shoulder_link"/>
      <child link="vx300s_left/shoulder_jointbody"/>
      <origin xyz="0.0 0.0 0.04805" rpy="0.0 0.0 0.0"/>
      <axis xyz="0.0 1.0 0.0"/>
      <limit lower="-1.85005" upper="1.25664" effort="100" velocity="100"/>
   </joint>
   <joint type="fixed" name="vx300s_left/shoulder_offset">
      <parent link="vx300s_left/shoulder_jointbody"/>
      <child link="vx300s_left/upper_arm_link"/>
      <origin xyz="-0.0 -0.0 -0.0" rpy="0.0 0.0 0.0"/>
   </joint>
   <link name="vx300s_left/upper_forearm_link">
      <inertial>
         <origin xyz="0.105723 0.0 0.0" rpy="1.1374668575171039 -1.5553008182372066 2.0198960909557155"/>
         <mass value="0.322228"/>
         <inertia ixx="0.00144107" iyy="0.00134228" izz="0.000152047" ixy="0" ixz="0" iyz="0"/>
      </inertial>
      <visual name="vx300s_4_upper_forearm">
         <origin xyz="0.09150298272232402 4.669695453248377e-08 5.3351891878143013e-08" rpy="1.7079488359161843e-06 -1.5707947270180007 -3.1415926535509184"/>
         <geometry>
            <mesh filename="meshes/converted_vx300s_4_upper_forearm.stl"/>
         </geometry>
         <material name="white"/>
      </visual>
   </link>
   <link name="vx300s_left/elbow_jointbody">
      <inertial>
         <origin xyz="0.0 0.0 0.0" rpy="0.0 0.0 0.0"/>
         <mass value="0.001"/>
         <inertia ixx="1e-09" iyy="1e-09" izz="1e-09" ixy="0" ixz="0" iyz="0"/>
      </inertial>
   </link>
   <joint type="revolute" name="vx300s_left/elbow">
      <parent link="vx300s_left/upper_arm_link"/>
      <child link="vx300s_left/elbow_jointbody"/>
      <origin xyz="0.05955 0.0 0.3" rpy="0.0 0.0 0.0"/>
      <axis xyz="0.0 1.0 0.0"/>
      <limit lower="-1.76278" upper="1.6057" effort="100" velocity="100"/>
   </joint>
   <joint type="fixed" name="vx300s_left/elbow_offset">
      <parent link="vx300s_left/elbow_jointbody"/>
      <child link="vx300s_left/upper_forearm_link"/>
      <origin xyz="-0.0 -0.0 -0.0" rpy="0.0 0.0 0.0"/>
   </joint>
   <link name="vx300s_left/lower_forearm_link">
      <inertial>
         <origin xyz="0.0513477 0.00680462 0.0" rpy="0.22582711793583052 1.5707963267948966 0.0"/>
         <mass value="0.414823"/>
         <inertia ixx="0.0005911" iyy="0.000546493" izz="0.000155707" ixy="0" ixz="0" iyz="0"/>
      </inertial>
      <visual name="vx300s_5_lower_forearm">
         <origin xyz="0.046863465778959855 0.006061610481320571 -3.606874328682953e-06" rpy="-1.7440697971477959 1.569683890548875 -1.9146386257440273"/>
         <geometry>
            <mesh filename="meshes/converted_vx300s_5_lower_forearm.stl"/>
         </geometry>
         <material name="white"/>
      </visual>
   </link>
   <link name="vx300s_left/forearm_roll_jointbody">
      <inertial>
         <origin xyz="0.0 0.0 0.0" rpy="0.0 0.0 0.0"/>
         <mass value="0.001"/>
         <inertia ixx="1e-09" iyy="1e-09" izz="1e-09" ixy="0" ixz="0" iyz="0"/>
      </inertial>
   </link>
   <joint type="revolute" name="vx300s_left/forearm_roll">
      <parent link="vx300s_left/upper_forearm_link"/>
      <child link="vx300s_left/forearm_roll_jointbody"/>
      <origin xyz="0.2 0.0 0.0" rpy="0.0 0.0 0.0"/>
      <axis xyz="1.0 0.0 0.0"/>
      <limit lower="-3.14158" upper="3.14158" effort="100" velocity="100"/>
   </joint>
   <joint type="fixed" name="vx300s_left/forearm_roll_offset">
      <parent link="vx300s_left/forearm_roll_jointbody"/>
      <child link="vx300s_left/lower_forearm_link"/>
      <origin xyz="-0.0 -0.0 -0.0" rpy="0.0 0.0 0.0"/>
   </joint>
   <link name="vx300s_left/wrist_link">
      <inertial>
         <origin xyz="0.046743 -7.6652e-06 0.010565" rpy="0.008277755597094094 -1.1517912606217704 3.138606936598997"/>
         <mass value="0.115395"/>
         <inertia ixx="5.45707e-05" iyy="4.63101e-05" izz="4.32692e-05" ixy="0" ixz="0" iyz="0"/>
      </inertial>
      <visual name="vx300s_6_wrist">
         <origin xyz="0.04164133231863641 -0.00016056442250253158 0.00784793199347111" rpy="0.0 -1.3314861466609826 3.141592653589793"/>
         <geometry>
            <mesh filename="meshes/converted_vx300s_6_wrist.stl"/>
         </geometry>
         <material name="white"/>
      </visual>
   </link>
   <link name="vx300s_left/wrist_angle_jointbody">
      <inertial>
         <origin xyz="0.0 0.0 0.0" rpy="0.0 0.0 0.0"/>
         <mass value="0.001"/>
         <inertia ixx="1e-09" iyy="1e-09" izz="1e-09" ixy="0" ixz="0" iyz="0"/>
      </inertial>
   </link>
   <joint type="revolute" name="vx300s_left/wrist_angle">
      <parent link="vx300s_left/lower_forearm_link"/>
      <child link="vx300s_left/wrist_angle_jointbody"/>
      <origin xyz="0.1 0.0 0.0" rpy="0.0 0.0 0.0"/>
      <axis xyz="0.0 1.0 0.0"/>
      <limit lower="-1.8675" upper="2.23402" effort="100" velocity="100"/>
   </joint>
   <joint type="fixed" name="vx300s_left/wrist_angle_offset">
      <parent link="vx300s_left/wrist_angle_jointbody"/>
      <child link="vx300s_left/wrist_link"/>
      <origin xyz="-0.0 -0.0 -0.0" rpy="0.0 0.0 0.0"/>
   </joint>
   <link name="vx300s_left/gripper_link">
      <inertial>
         <origin xyz="0.0395662 -2.56311e-07 0.00400649" rpy="1.5696062015365904 -1.0024837628865453 0.000953641922889048"/>
         <mass value="0.251652"/>
         <inertia ixx="0.000689546" iyy="0.000650316" izz="0.000468142" ixy="0" ixz="0" iyz="0"/>
      </inertial>
      <visual name="vx300s_7_gripper">
         <origin xyz="0.019865668160067514 -7.005736523051254e-09 0.010150989601905417" rpy="0.5043852668531259 0.0 1.5707963267948966"/>
         <geometry>
            <mesh filename="meshes/converted_vx300s_7_gripper.stl"/>
         </geometry>
         <material name="white"/>
      </visual>
      <visual name="vx300s_9_gripper_bar">
         <origin xyz="0.049328257075604384 -4.4734997897412666e-07 -0.0012095709992750946" rpy="1.570620783254074 -0.19393160010183896 -3.1415756706681535"/>
         <geometry>
            <mesh filename="meshes/converted_vx300s_9_gripper_bar.stl"/>
         </geometry>
         <material name="white"/>
      </visual>
   </link>
   <link name="vx300s_left/wrist_rotate_jointbody">
      <inertial>
         <origin xyz="0.0 0.0 0.0" rpy="0.0 0.0 0.0"/>
         <mass value="0.001"/>
         <inertia ixx="1e-09" iyy="1e-09" izz="1e-09" ixy="0" ixz="0" iyz="0"/>
      </inertial>
   </link>
   <joint type="revolute" name="vx300s_left/wrist_rotate">
      <parent link="vx300s_left/wrist_link"/>
      <child link="vx300s_left/wrist_rotate_jointbody"/>
      <origin xyz="0.069744 0.0 0.0" rpy="0.0 0.0 0.0"/>
      <axis xyz="1.0 0.0 0.0"/>
      <limit lower="-3.14158" upper="3.14158" effort="100" velocity="100"/>
   </joint>
   <joint type="fixed" name="vx300s_left/wrist_rotate_offset">
      <parent link="vx300s_left/wrist_rotate_jointbody"/>
      <child link="vx300s_left/gripper_link"/>
      <origin xyz="-0.0 -0.0 -0.0" rpy="0.0 0.0 0.0"/>
   </joint>
   <link name="vx300s_left/camera_focus">
      <inertial>
         <origin xyz="0.15 0.0 0.01" rpy="0.0 0.0 0.0"/>
         <mass value="0.0"/>
         <inertia ixx="0.0" iyy="0.0" izz="0.0" ixy="0" ixz="0" iyz="0"/>
      </inertial>
   </link>
   <joint type="fixed" name="vx300s_left/gripper_link2vx300s_left/camera_focus_fixed">
      <parent link="vx300s_left/gripper_link"/>
      <child link="vx300s_left/camera_focus"/>
      <origin xyz="0.15 0.0 0.01" rpy="0.0 0.0 0.0"/>
   </joint>
   <link name="vx300s_left/gripper_prop_link">
      <inertial>
         <origin xyz="0.002378 2.85e-08 0.0" rpy="2.229034153159594 0.0 3.141592653589793"/>
         <mass value="0.008009"/>
         <inertia ixx="4.2979e-06" iyy="2.8868e-06" izz="1.5314e-06" ixy="0" ixz="0" iyz="0"/>
      </inertial>
      <visual name="vx300s_8_gripper_prop">
         <origin xyz="0.0 0.0002406316223018793 -0.0005006405808746677" rpy="-0.055920927342721694 0.0 3.141592653589793"/>
         <geometry>
            <mesh filename="meshes/converted_vx300s_8_gripper_prop.stl"/>
         </geometry>
         <material name="white"/>
      </visual>
   </link>
   <joint type="fixed" name="vx300s_left/gripper_link2vx300s_left/gripper_prop_link_fixed">
      <parent link="vx300s_left/gripper_link"/>
      <child link="vx300s_left/gripper_prop_link"/>
      <origin xyz="0.0485 0.0 0.0" rpy="0.0 0.0 0.0"/>
   </joint>
   <link name="vx300s_left/left_finger_link">
      <inertial>
         <origin xyz="0.017344 -0.0060692 0.0" rpy="1.5707963267948966 2.220446049250313e-16 -1.7642899709575044"/>
         <mass value="0.034796"/>
         <inertia ixx="2.48003e-05" iyy="1.417e-05" izz="1.20797e-05" ixy="0" ixz="0" iyz="0"/>
      </inertial>
      <visual name="vx300s_10_gripper_finger_left">
         <origin xyz="0.024758826833880605 -0.013231640423985176 0.002021349057495323" rpy="-1.266740490927044 -0.014276180225681001 -1.6709736312279375"/>
         <geometry>
            <mesh filename="meshes/converted_vx300s_10_gripper_finger_left.stl"/>
         </geometry>
         <material name="white"/>
      </visual>
   </link>
   <link name="vx300s_left/left_finger_jointbody">
      <inertial>
         <origin xyz="0.0 0.0 0.0" rpy="0.0 0.0 0.0"/>
         <mass value="0.001"/>
         <inertia ixx="1e-09" iyy="1e-09" izz="1e-09" ixy="0" ixz="0" iyz="0"/>
      </inertial>
   </link>

    <!-- [MODIFIED] Replaced fixed gripper joints with revolute and mimic joints, ensuring correct child link -->
    <joint type="revolute" name="vx300s_left/gripper_joint">
        <parent link="vx300s_left/gripper_link"/>
        <child link="vx300s_left/left_finger_jointbody"/>
        <origin xyz="0.0687 0.0 0.0" rpy="0.0 0.0 0.0"/>
        <axis xyz="0 0 1"/>
        <limit lower="-0.03" upper="0.03" effort="10" velocity="1.0"/>
    </joint>

    <joint name="vx300s_left/right_finger_mimic_joint" type="revolute">
        <parent link="vx300s_left/gripper_link"/>
        <child link="vx300s_left/right_finger_jointbody"/>
        <origin xyz="0.0687 0.0 0.0" rpy="0.0 0.0 0.0"/>
        <axis xyz="0 0 1"/>
        <limit lower="-0.03" upper="0.03" effort="10" velocity="1.0"/>
        <mimic joint="vx300s_left/gripper_joint" multiplier="-1" offset="0"/>
    </joint>
    <!-- End of modification for left gripper -->

   <joint type="fixed" name="vx300s_left/left_finger_offset">
      <parent link="vx300s_left/left_finger_jointbody"/>
      <child link="vx300s_left/left_finger_link"/>
      <origin xyz="-0.0 -0.0 -0.0" rpy="0.0 0.0 0.0"/>
   </joint>
   <link name="vx300s_left/right_finger_link">
      <inertial>
         <origin xyz="0.017344 0.0060692 0.0" rpy="-1.5707963267948968 0.0 -1.7642678806504266"/>
         <mass value="0.034796"/>
         <inertia ixx="2.48002e-05" iyy="1.417e-05" izz="1.20798e-05" ixy="0" ixz="0" iyz="0"/>
      </inertial>
      <visual name="vx300s_10_gripper_finger_right">
         <origin xyz="0.024759026771782794 0.01323824786246524 0.0021447619367371564" rpy="-1.2670945657039128 0.011104510487408792 -1.4706258573054107"/>
         <geometry>
            <mesh filename="meshes/converted_vx300s_10_gripper_finger_right.stl"/>
         </geometry>
         <material name="white"/>
      </visual>
   </link>
   <link name="vx300s_left/right_finger_jointbody">
      <inertial>
         <origin xyz="0.0 0.0 0.0" rpy="0.0 0.0 0.0"/>
         <mass value="0.001"/>
         <inertia ixx="1e-09" iyy="1e-09" izz="1e-09" ixy="0" ixz="0" iyz="0"/>
      </inertial>
   </link>
   <joint type="fixed" name="vx300s_left/right_finger_offset">
      <parent link="vx300s_left/right_finger_jointbody"/>
      <child link="vx300s_left/right_finger_link"/>
      <origin xyz="-0.0 -0.0 -0.0" rpy="0.0 0.0 0.0"/>
   </joint>
   <link name="vx300s_right">
      <inertial>
         <origin xyz="-0.03784382902588578 2.8602218040311562e-08 0.02913398715850308" rpy="0.0 -1.542175771520014 3.141592653589793"/>
         <mass value="2.0847071932290793"/>
         <inertia ixx="0.012833192082346331" iyy="0.010945761787034795" izz="0.003713297010020567" ixy="0" ixz="0" iyz="0"/>
      </inertial>
      <visual name="vx300s_1_base">
         <origin xyz="-0.03784382902588578 2.8602218040311562e-08 0.02913398715850308" rpy="0.0 -1.542175771520014 3.141592653589793"/>
         <geometry>
            <mesh filename="meshes/converted_vx300s_1_base.stl"/>
         </geometry>
         <material name="white"/>
      </visual>
   </link>
   <joint type="fixed" name="world2vx300s_right_fixed">
      <parent link="world"/>
      <child link="vx300s_right"/>
      <origin xyz="0.469 0.5 0.0" rpy="0.0 0.0 -3.1415853071697932"/>
   </joint>
   <link name="vx300s_right/shoulder_link">
      <inertial>
         <origin xyz="0.000259233 -3.3552e-06 0.0116129" rpy="1.5700255645350394 -1.4773483355619266 -3.140821891329936"/>
         <mass value="0.798614"/>
         <inertia ixx="0.00120156" iyy="0.00113744" izz="0.0009388" ixy="0" ixz="0" iyz="0"/>
      </inertial>
      <visual name="vx300s_2_shoulder">
         <origin xyz="0.0006325719563753528 7.750435013387896e-11 0.02039145786401413" rpy="-1.5707963267948966 -1.5707963267948966 0.0"/>
         <geometry>
            <mesh filename="meshes/converted_vx300s_2_shoulder.stl"/>
         </geometry>
         <material name="white"/>
      </visual>
   </link>
   <link name="vx300s_right/waist_jointbody">
      <inertial>
         <origin xyz="0.0 0.0 0.0" rpy="0.0 0.0 0.0"/>
         <mass value="0.001"/>
         <inertia ixx="1e-09" iyy="1e-09" izz="1e-09" ixy="0" ixz="0" iyz="0"/>
      </inertial>
   </link>
   <joint type="revolute" name="vx300s_right/waist">
      <parent link="vx300s_right"/>
      <child link="vx300s_right/waist_jointbody"/>
      <origin xyz="0.0 0.0 0.079" rpy="0.0 0.0 0.0"/>
      <axis xyz="0.0 0.0 1.0"/>
      <limit lower="-3.14158" upper="3.14158" effort="100" velocity="100"/>
   </joint>
   <joint type="fixed" name="vx300s_right/waist_offset">
      <parent link="vx300s_right/waist_jointbody"/>
      <child link="vx300s_right/shoulder_link"/>
      <origin xyz="-0.0 -0.0 -0.0" rpy="0.0 0.0 0.0"/>
   </joint>
   <link name="vx300s_right/upper_arm_link">
      <inertial>
         <origin xyz="0.0206949 4e-10 0.226459" rpy="0.0 -0.14582079239240509 3.141592653589793"/>
         <mass value="0.792592"/>
         <inertia ixx="0.00911338" iyy="0.008925" izz="0.000759317" ixy="0" ixz="0" iyz="0"/>
      </inertial>
      <visual name="vx300s_3_upper_arm">
         <origin xyz="0.01879484718495746 1.0688876592918973e-09 0.20381388688857144" rpy="0.0 -0.1374703277880469 3.141592653589793"/>
         <geometry>
            <mesh filename="meshes/converted_vx300s_3_upper_arm.stl"/>
         </geometry>
         <material name="white"/>
      </visual>
   </link>
   <link name="vx300s_right/shoulder_jointbody">
      <inertial>
         <origin xyz="0.0 0.0 0.0" rpy="0.0 0.0 0.0"/>
         <mass value="0.001"/>
         <inertia ixx="1e-09" iyy="1e-09" izz="1e-09" ixy="0" ixz="0" iyz="0"/>
      </inertial>
   </link>
   <joint type="revolute" name="vx300s_right/shoulder">
      <parent link="vx300s_right/shoulder_link"/>
      <child link="vx300s_right/shoulder_jointbody"/>
      <origin xyz="0.0 0.0 0.04805" rpy="0.0 0.0 0.0"/>
      <axis xyz="0.0 1.0 0.0"/>
      <limit lower="-1.85005" upper="1.25664" effort="100" velocity="100"/>
   </joint>
   <joint type="fixed" name="vx300s_right/shoulder_offset">
      <parent link="vx300s_right/shoulder_jointbody"/>
      <child link="vx300s_right/upper_arm_link"/>
      <origin xyz="-0.0 -0.0 -0.0" rpy="0.0 0.0 0.0"/>
   </joint>
   <link name="vx300s_right/upper_forearm_link">
      <inertial>
         <origin xyz="0.105723 0.0 0.0" rpy="1.1374668575171039 -1.5553008182372066 2.0198960909557155"/>
         <mass value="0.322228"/>
         <inertia ixx="0.00144107" iyy="0.00134228" izz="0.000152047" ixy="0" ixz="0" iyz="0"/>
      </inertial>
      <visual name="vx300s_4_upper_forearm">
         <origin xyz="0.09150298272232402 4.669695453248377e-08 5.3351891878143013e-08" rpy="1.7079488359161843e-06 -1.5707947270180007 -3.1415926535509184"/>
         <geometry>
            <mesh filename="meshes/converted_vx300s_4_upper_forearm.stl"/>
         </geometry>
         <material name="white"/>
      </visual>
   </link>
   <link name="vx300s_right/elbow_jointbody">
      <inertial>
         <origin xyz="0.0 0.0 0.0" rpy="0.0 0.0 0.0"/>
         <mass value="0.001"/>
         <inertia ixx="1e-09" iyy="1e-09" izz="1e-09" ixy="0" ixz="0" iyz="0"/>
      </inertial>
   </link>
   <joint type="revolute" name="vx300s_right/elbow">
      <parent link="vx300s_right/upper_arm_link"/>
      <child link="vx300s_right/elbow_jointbody"/>
      <origin xyz="0.05955 0.0 0.3" rpy="0.0 0.0 0.0"/>
      <axis xyz="0.0 1.0 0.0"/>
      <limit lower="-1.76278" upper="1.6057" effort="100" velocity="100"/>
   </joint>
   <joint type="fixed" name="vx300s_right/elbow_offset">
      <parent link="vx300s_right/elbow_jointbody"/>
      <child link="vx300s_right/upper_forearm_link"/>
      <origin xyz="-0.0 -0.0 -0.0" rpy="0.0 0.0 0.0"/>
   </joint>
   <link name="vx300s_right/lower_forearm_link">
      <inertial>
         <origin xyz="0.0513477 0.00680462 0.0" rpy="0.22582711793583052 1.5707963267948966 0.0"/>
         <mass value="0.414823"/>
         <inertia ixx="0.0005911" iyy="0.000546493" izz="0.000155707" ixy="0" ixz="0" iyz="0"/>
      </inertial>
      <visual name="vx300s_5_lower_forearm">
         <origin xyz="0.046863465778959855 0.006061610481320571 -3.606874328682953e-06" rpy="-1.7440697971477959 1.569683890548875 -1.9146386257440273"/>
         <geometry>
            <mesh filename="meshes/converted_vx300s_5_lower_forearm.stl"/>
         </geometry>
         <material name="white"/>
      </visual>
   </link>
   <link name="vx300s_right/forearm_roll_jointbody">
      <inertial>
         <origin xyz="0.0 0.0 0.0" rpy="0.0 0.0 0.0"/>
         <mass value="0.001"/>
         <inertia ixx="1e-09" iyy="1e-09" izz="1e-09" ixy="0" ixz="0" iyz="0"/>
      </inertial>
   </link>
   <joint type="revolute" name="vx300s_right/forearm_roll">
      <parent link="vx300s_right/upper_forearm_link"/>
      <child link="vx300s_right/forearm_roll_jointbody"/>
      <origin xyz="0.2 0.0 0.0" rpy="0.0 0.0 0.0"/>
      <axis xyz="1.0 0.0 0.0"/>
      <limit lower="-3.14158" upper="3.14158" effort="100" velocity="100"/>
   </joint>
   <joint type="fixed" name="vx300s_right/forearm_roll_offset">
      <parent link="vx300s_right/forearm_roll_jointbody"/>
      <child link="vx300s_right/lower_forearm_link"/>
      <origin xyz="-0.0 -0.0 -0.0" rpy="0.0 0.0 0.0"/>
   </joint>
   <link name="vx300s_right/wrist_link">
      <inertial>
         <origin xyz="0.046743 -7.6652e-06 0.010565" rpy="0.008277755597094094 -1.1517912606217704 3.138606936598997"/>
         <mass value="0.115395"/>
         <inertia ixx="5.45707e-05" iyy="4.63101e-05" izz="4.32692e-05" ixy="0" ixz="0" iyz="0"/>
      </inertial>
      <visual name="vx300s_6_wrist">
         <origin xyz="0.04164133231863641 -0.00016056442250253158 0.00784793199347111" rpy="0.0 -1.3314861466609826 3.141592653589793"/>
         <geometry>
            <mesh filename="meshes/converted_vx300s_6_wrist.stl"/>
         </geometry>
         <material name="white"/>
      </visual>
   </link>
   <link name="vx300s_right/wrist_angle_jointbody">
      <inertial>
         <origin xyz="0.0 0.0 0.0" rpy="0.0 0.0 0.0"/>
         <mass value="0.001"/>
         <inertia ixx="1e-09" iyy="1e-09" izz="1e-09" ixy="0" ixz="0" iyz="0"/>
      </inertial>
   </link>
   <joint type="revolute" name="vx300s_right/wrist_angle">
      <parent link="vx300s_right/lower_forearm_link"/>
      <child link="vx300s_right/wrist_angle_jointbody"/>
      <origin xyz="0.1 0.0 0.0" rpy="0.0 0.0 0.0"/>
      <axis xyz="0.0 1.0 0.0"/>
      <limit lower="-1.8675" upper="2.23402" effort="100" velocity="100"/>
   </joint>
   <joint type="fixed" name="vx300s_right/wrist_angle_offset">
      <parent link="vx300s_right/wrist_angle_jointbody"/>
      <child link="vx300s_right/wrist_link"/>
      <origin xyz="-0.0 -0.0 -0.0" rpy="0.0 0.0 0.0"/>
   </joint>
   <link name="vx300s_right/gripper_link">
      <inertial>
         <origin xyz="0.0395662 -2.56311e-07 0.00400649" rpy="1.5696062015365904 -1.0024837628865453 0.000953641922889048"/>
         <mass value="0.251652"/>
         <inertia ixx="0.000689546" iyy="0.000650316" izz="0.000468142" ixy="0" ixz="0" iyz="0"/>
      </inertial>
      <visual name="vx300s_7_gripper">
         <origin xyz="0.019865668160067514 -7.005736523051254e-09 0.010150989601905417" rpy="0.5043852668531259 0.0 1.5707963267948966"/>
         <geometry>
            <mesh filename="meshes/converted_vx300s_7_gripper.stl"/>
         </geometry>
         <material name="white"/>
      </visual>
      <visual name="vx300s_9_gripper_bar">
         <origin xyz="0.049328257075604384 -4.4734997897412666e-07 -0.0012095709992750946" rpy="1.570620783254074 -0.19393160010183896 -3.1415756706681535"/>
         <geometry>
            <mesh filename="meshes/converted_vx300s_9_gripper_bar.stl"/>
         </geometry>
         <material name="white"/>
      </visual>
   </link>
   <link name="vx300s_right/wrist_rotate_jointbody">
      <inertial>
         <origin xyz="0.0 0.0 0.0" rpy="0.0 0.0 0.0"/>
         <mass value="0.001"/>
         <inertia ixx="1e-09" iyy="1e-09" izz="1e-09" ixy="0" ixz="0" iyz="0"/>
      </inertial>
   </link>
   <joint type="revolute" name="vx300s_right/wrist_rotate">
      <parent link="vx300s_right/wrist_link"/>
      <child link="vx300s_right/wrist_rotate_jointbody"/>
      <origin xyz="0.069744 0.0 0.0" rpy="0.0 0.0 0.0"/>
      <axis xyz="1.0 0.0 0.0"/>
      <limit lower="-3.14158" upper="3.14158" effort="100" velocity="100"/>
   </joint>
   <joint type="fixed" name="vx300s_right/wrist_rotate_offset">
      <parent link="vx300s_right/wrist_rotate_jointbody"/>
      <child link="vx300s_right/gripper_link"/>
      <origin xyz="-0.0 -0.0 -0.0" rpy="0.0 0.0 0.0"/>
   </joint>
   <link name="vx300s_right/camera_focus">
      <inertial>
         <origin xyz="0.15 0.0 0.01" rpy="0.0 0.0 0.0"/>
         <mass value="0.0"/>
         <inertia ixx="0.0" iyy="0.0" izz="0.0" ixy="0" ixz="0" iyz="0"/>
      </inertial>
   </link>
   <joint type="fixed" name="vx300s_right/gripper_link2vx300s_right/camera_focus_fixed">
      <parent link="vx300s_right/gripper_link"/>
      <child link="vx300s_right/camera_focus"/>
      <origin xyz="0.15 0.0 0.01" rpy="0.0 0.0 0.0"/>
   </joint>
   <link name="vx300s_right/gripper_prop_link">
      <inertial>
         <origin xyz="0.002378 2.85e-08 0.0" rpy="2.229034153159594 0.0 3.141592653589793"/>
         <mass value="0.008009"/>
         <inertia ixx="4.2979e-06" iyy="2.8868e-06" izz="1.5314e-06" ixy="0" ixz="0" iyz="0"/>
      </inertial>
      <visual name="vx300s_8_gripper_prop">
         <origin xyz="0.0 0.0002406316223018793 -0.0005006405808746677" rpy="-0.055920927342721694 0.0 3.141592653589793"/>
         <geometry>
            <mesh filename="meshes/converted_vx300s_8_gripper_prop.stl"/>
         </geometry>
         <material name="white"/>
      </visual>
   </link>
   <joint type="fixed" name="vx300s_right/gripper_link2vx300s_right/gripper_prop_link_fixed">
      <parent link="vx300s_right/gripper_link"/>
      <child link="vx300s_right/gripper_prop_link"/>
      <origin xyz="0.0485 0.0 0.0" rpy="0.0 0.0 0.0"/>
   </joint>
   <link name="vx300s_right/left_finger_link">
      <inertial>
         <origin xyz="0.017344 -0.0060692 0.0" rpy="1.5707963267948966 2.220446049250313e-16 -1.7642899709575044"/>
         <mass value="0.034796"/>
         <inertia ixx="2.48003e-05" iyy="1.417e-05" izz="1.20797e-05" ixy="0" ixz="0" iyz="0"/>
      </inertial>
      <visual name="vx300s_10_gripper_finger_left">
         <origin xyz="0.024758826833880605 -0.013231640423985176 0.002021349057495323" rpy="-1.266740490927044 -0.014276180225681001 -1.6709736312279375"/>
         <geometry>
            <mesh filename="meshes/converted_vx300s_10_gripper_finger_left.stl"/>
         </geometry>
         <material name="white"/>
      </visual>
   </link>
   <link name="vx300s_right/left_finger_jointbody">
      <inertial>
         <origin xyz="0.0 0.0 0.0" rpy="0.0 0.0 0.0"/>
         <mass value="0.001"/>
         <inertia ixx="1e-09" iyy="1e-09" izz="1e-09" ixy="0" ixz="0" iyz="0"/>
      </inertial>
   </link>
    
    <!-- [MODIFIED] Replaced fixed gripper joints with revolute and mimic joints, ensuring correct child link -->
    <joint type="revolute" name="vx300s_right/gripper_joint">
        <parent link="vx300s_right/gripper_link"/>
        <child link="vx300s_right/left_finger_jointbody"/>
        <origin xyz="0.0687 0.0 0.0" rpy="0.0 0.0 0.0"/>
        <axis xyz="0 0 1"/>
        <limit lower="-0.03" upper="0.03" effort="10" velocity="1.0"/>
    </joint>

    <joint name="vx300s_right/right_finger_mimic_joint" type="revolute">
        <parent link="vx300s_right/gripper_link"/>
        <child link="vx300s_right/right_finger_jointbody"/>
        <origin xyz="0.0687 0.0 0.0" rpy="0.0 0.0 0.0"/>
        <axis xyz="0 0 1"/>
        <limit lower="-0.03" upper="0.03" effort="10" velocity="1.0"/>
        <mimic joint="vx300s_right/gripper_joint" multiplier="-1" offset="0"/>
    </joint>
    <!-- End of modification for right gripper -->

   <joint type="fixed" name="vx300s_right/left_finger_offset">
      <parent link="vx300s_right/left_finger_jointbody"/>
      <child link="vx300s_right/left_finger_link"/>
      <origin xyz="-0.0 -0.0 -0.0" rpy="0.0 0.0 0.0"/>
   </joint>
   <link name="vx300s_right/right_finger_link">
      <inertial>
         <origin xyz="0.017344 0.0060692 0.0" rpy="-1.5707963267948968 0.0 -1.7642678806504266"/>
         <mass value="0.034796"/>
         <inertia ixx="2.48002e-05" iyy="1.417e-05" izz="1.20798e-05" ixy="0" ixz="0" iyz="0"/>
      </inertial>
      <visual name="vx300s_10_gripper_finger_right">
         <origin xyz="0.024759026771782794 0.01323824786246524 0.0021447619367371564" rpy="-1.2670945657039128 0.011104510487408792 -1.4706258573054107"/>
         <geometry>
            <mesh filename="meshes/converted_vx300s_10_gripper_finger_right.stl"/>
         </geometry>
         <material name="white"/>
      </visual>
   </link>
   <link name="vx300s_right/right_finger_jointbody">
      <inertial>
         <origin xyz="0.0 0.0 0.0" rpy="0.0 0.0 0.0"/>
         <mass value="0.001"/>
         <inertia ixx="1e-09" iyy="1e-09" izz="1e-09" ixy="0" ixz="0" iyz="0"/>
      </inertial>
   </link>
   <joint type="fixed" name="vx300s_right/right_finger_offset">
      <parent link="vx300s_right/right_finger_jointbody"/>
      <child link="vx300s_right/right_finger_link"/>
      <origin xyz="-0.0 -0.0 -0.0" rpy="0.0 0.0 0.0"/>
   </joint>
   <link name="box">
      <inertial>
         <origin xyz="0.0 0.0 0.0" rpy="0.0 0.0 0.0"/>
         <mass value="0.05"/>
         <inertia ixx="0.002" iyy="0.002" izz="0.002" ixy="0" ixz="0" iyz="0"/>
      </inertial>
   </link>
   <link name="red_box_joint_jointbody">
      <inertial>
         <origin xyz="0.0 0.0 0.0" rpy="0.0 0.0 0.0"/>
         <mass value="0.001"/>
         <inertia ixx="1e-09" iyy="1e-09" izz="1e-09" ixy="0" ixz="0" iyz="0"/>
      </inertial>
   </link>
   <joint type="fixed" name="red_box_joint">
      <parent link="world"/>
      <child link="red_box_joint_jointbody"/>
      <origin xyz="0.2 0.5 0.05" rpy="0.0 0.0 0.0"/>
   </joint>
   <joint type="fixed" name="red_box_joint_offset">
      <parent link="red_box_joint_jointbody"/>
      <child link="box"/>
      <origin xyz="-0.0 -0.0 -0.0" rpy="0.0 0.0 0.0"/>
   </joint>
   <material name="white">
      <color rgba="1 1 1 1"/>
   </material>
</robot>
